2025-08-16 15:05:38,094 - INFO - Logger initialized and ready.
2025-08-16 15:05:59,584 - INFO - Language loaded: zh_CN
2025-08-16 15:05:59,585 - ERROR - 程序运行时发生未处理的异常
Traceback (most recent call last):
  File "J:\V3_Mod_Localization_Factory\scripts\main.py", line 411, in <module>
    main()
  File "J:\V3_Mod_Localization_Factory\scripts\main.py", line 271, in main
    logger.setup_logging()
    ^^^^^^^^^^^^^^^^^^^^
AttributeError: module 'scripts.utils.logger' has no attribute 'setup_logging'. Did you mean: 'setup_logger'?
